2019-12-15 23:31:15,444 ERROR: Exception on /user/b [GET] [in /Users/bkhanal/microblog/venv/lib/python3.7/site-packages/flask/app.py:1891]
Traceback (most recent call last):
  File "/Users/bkhanal/microblog/venv/lib/python3.7/site-packages/flask/app.py", line 2446, in wsgi_app
    response = self.full_dispatch_request()
  File "/Users/bkhanal/microblog/venv/lib/python3.7/site-packages/flask/app.py", line 1951, in full_dispatch_request
    rv = self.handle_user_exception(e)
  File "/Users/bkhanal/microblog/venv/lib/python3.7/site-packages/flask/app.py", line 1820, in handle_user_exception
    reraise(exc_type, exc_value, tb)
  File "/Users/bkhanal/microblog/venv/lib/python3.7/site-packages/flask/_compat.py", line 39, in reraise
    raise value
  File "/Users/bkhanal/microblog/venv/lib/python3.7/site-packages/flask/app.py", line 1949, in full_dispatch_request
    rv = self.dispatch_request()
  File "/Users/bkhanal/microblog/venv/lib/python3.7/site-packages/flask/app.py", line 1935, in dispatch_request
    return self.view_functions[rule.endpoint](**req.view_args)
  File "/Users/bkhanal/microblog/venv/lib/python3.7/site-packages/flask_login/utils.py", line 261, in decorated_view
    return func(*args, **kwargs)
  File "/Users/bkhanal/microblog/app/routes.py", line 135, in user
    next_url=next_url, prev_url=prev_url)
  File "/Users/bkhanal/microblog/venv/lib/python3.7/site-packages/flask/templating.py", line 140, in render_template
    ctx.app,
  File "/Users/bkhanal/microblog/venv/lib/python3.7/site-packages/flask/templating.py", line 120, in _render
    rv = template.render(context)
  File "/Users/bkhanal/microblog/venv/lib/python3.7/site-packages/jinja2/asyncsupport.py", line 76, in render
    return original_render(self, *args, **kwargs)
  File "/Users/bkhanal/microblog/venv/lib/python3.7/site-packages/jinja2/environment.py", line 1008, in render
    return self.environment.handle_exception(exc_info, True)
  File "/Users/bkhanal/microblog/venv/lib/python3.7/site-packages/jinja2/environment.py", line 780, in handle_exception
    reraise(exc_type, exc_value, tb)
  File "/Users/bkhanal/microblog/venv/lib/python3.7/site-packages/jinja2/_compat.py", line 37, in reraise
    raise value.with_traceback(tb)
  File "/Users/bkhanal/microblog/app/templates/user.html", line 1, in top-level template code
    {% extends "base.html" %}
  File "/Users/bkhanal/microblog/app/templates/base.html", line 1, in top-level template code
    {% extends 'bootstrap/base.html' %}
  File "/Users/bkhanal/microblog/venv/lib/python3.7/site-packages/flask_bootstrap/templates/bootstrap/base.html", line 1, in top-level template code
    {% block doc -%}
  File "/Users/bkhanal/microblog/venv/lib/python3.7/site-packages/flask_bootstrap/templates/bootstrap/base.html", line 4, in block "doc"
    {%- block html %}
  File "/Users/bkhanal/microblog/venv/lib/python3.7/site-packages/flask_bootstrap/templates/bootstrap/base.html", line 20, in block "html"
    {% block body -%}
  File "/Users/bkhanal/microblog/venv/lib/python3.7/site-packages/flask_bootstrap/templates/bootstrap/base.html", line 23, in block "body"
    {% block content -%}
  File "/Users/bkhanal/microblog/app/templates/base.html", line 52, in block "content"
    {% block app_content %}{% endblock %}
  File "/Users/bkhanal/microblog/app/templates/user.html", line 6, in block "app_content"
    <td width="256px"><img src="{{ user.avatar(256) }}"></td>
jinja2.exceptions.UndefinedError: 'app.models.User object' has no attribute 'avatar'
2019-12-15 23:32:02,343 INFO: Microblog startup [in /Users/bkhanal/microblog/app/__init__.py:48]
2019-12-15 23:32:26,756 INFO: Microblog startup [in /Users/bkhanal/microblog/app/__init__.py:48]
2019-12-15 23:33:36,744 INFO: Microblog startup [in /Users/bkhanal/microblog/app/__init__.py:48]
2019-12-15 23:34:42,915 INFO: Microblog startup [in /Users/bkhanal/microblog/app/__init__.py:48]
2019-12-15 23:53:36,594 INFO: Microblog startup [in /Users/bkhanal/microblog/app/__init__.py:48]
2019-12-16 01:03:30,289 INFO: Microblog startup [in /Users/bkhanal/microblog/app/__init__.py:48]
2019-12-16 01:03:52,210 INFO: Microblog startup [in /Users/bkhanal/microblog/app/__init__.py:48]
2019-12-16 01:04:02,039 ERROR: Exception on /login [POST] [in /Users/bkhanal/microblog/venv/lib/python3.7/site-packages/flask/app.py:1891]
Traceback (most recent call last):
  File "/Users/bkhanal/microblog/venv/lib/python3.7/site-packages/sqlalchemy/ext/declarative/clsregistry.py", line 294, in __call__
    x = eval(self.arg, globals(), self._dict)
  File "<string>", line 1, in <module>
NameError: name 'PostLike' is not defined

During handling of the above exception, another exception occurred:

Traceback (most recent call last):
  File "/Users/bkhanal/microblog/venv/lib/python3.7/site-packages/flask/app.py", line 2446, in wsgi_app
    response = self.full_dispatch_request()
  File "/Users/bkhanal/microblog/venv/lib/python3.7/site-packages/flask/app.py", line 1951, in full_dispatch_request
    rv = self.handle_user_exception(e)
  File "/Users/bkhanal/microblog/venv/lib/python3.7/site-packages/flask/app.py", line 1820, in handle_user_exception
    reraise(exc_type, exc_value, tb)
  File "/Users/bkhanal/microblog/venv/lib/python3.7/site-packages/flask/_compat.py", line 39, in reraise
    raise value
  File "/Users/bkhanal/microblog/venv/lib/python3.7/site-packages/flask/app.py", line 1949, in full_dispatch_request
    rv = self.dispatch_request()
  File "/Users/bkhanal/microblog/venv/lib/python3.7/site-packages/flask/app.py", line 1935, in dispatch_request
    return self.view_functions[rule.endpoint](**req.view_args)
  File "/Users/bkhanal/microblog/app/routes.py", line 61, in login
    user = User.query.filter_by(username=form.username.data).first()
  File "/Users/bkhanal/microblog/venv/lib/python3.7/site-packages/flask_sqlalchemy/__init__.py", line 517, in __get__
    mapper = orm.class_mapper(type)
  File "/Users/bkhanal/microblog/venv/lib/python3.7/site-packages/sqlalchemy/orm/base.py", line 441, in class_mapper
    mapper = _inspect_mapped_class(class_, configure=configure)
  File "/Users/bkhanal/microblog/venv/lib/python3.7/site-packages/sqlalchemy/orm/base.py", line 420, in _inspect_mapped_class
    mapper._configure_all()
  File "/Users/bkhanal/microblog/venv/lib/python3.7/site-packages/sqlalchemy/orm/mapper.py", line 1337, in _configure_all
    configure_mappers()
  File "/Users/bkhanal/microblog/venv/lib/python3.7/site-packages/sqlalchemy/orm/mapper.py", line 3248, in configure_mappers
    mapper._post_configure_properties()
  File "/Users/bkhanal/microblog/venv/lib/python3.7/site-packages/sqlalchemy/orm/mapper.py", line 1947, in _post_configure_properties
    prop.init()
  File "/Users/bkhanal/microblog/venv/lib/python3.7/site-packages/sqlalchemy/orm/interfaces.py", line 196, in init
    self.do_init()
  File "/Users/bkhanal/microblog/venv/lib/python3.7/site-packages/sqlalchemy/orm/relationships.py", line 1878, in do_init
    self._process_dependent_arguments()
  File "/Users/bkhanal/microblog/venv/lib/python3.7/site-packages/sqlalchemy/orm/relationships.py", line 1907, in _process_dependent_arguments
    setattr(self, attr, attr_value())
  File "/Users/bkhanal/microblog/venv/lib/python3.7/site-packages/sqlalchemy/ext/declarative/clsregistry.py", line 306, in __call__
    % (self.prop.parent, self.arg, n.args[0], self.cls)
sqlalchemy.exc.InvalidRequestError: When initializing mapper mapped class User->user, expression 'PostLike.user_id' failed to locate a name ("name 'PostLike' is not defined"). If this is a class name, consider adding this relationship() to the <class 'app.models.User'> class after both dependent classes have been defined.
2019-12-16 01:05:00,649 INFO: Microblog startup [in /Users/bkhanal/microblog/app/__init__.py:48]
